Workbook
Name Slicer_Diabetes_Status: #N/A
Name Slicer_Weight_Status: #N/A

Sheet Customer Names
A1: Customer ID | B1: Last Name | C1: Prefix | D1: First Name | E1: Suffix
A2: Id1 | B2: Hawks | C2: Ms. | D2: Kelly
A3: Id2 | B3: Lehner | C3: Mr. | D3: Matthew D
A4: Id3 | B4: Lu | C4: Mr. | D4: Phil
A5: Id4 | B5: Osborne | C5: Ms. | D5: Kelsey
A6: Id5 | B6: Kadala | C6: Ms. | D6: Kristyn
A7: Id6 | B7: Baker | C7: Mr. | D7: Russell B
A8: Id7 | B8: Macpherson | C8: Mr. | D8: Scott
A9: Id8 | B9: Hallman | C9: Mr. | D9: Stephen
A10: Id9 | B10: Moran | C10: Mr. | D10: Patrick R
A11: Id10 | B11: Benner | C11: Ms. | D11: Brooke N
A12: Id11 | B12: Fierro Vargas | C12: Ms. | D12: Paola Andrea
A13: Id12 | B13: Franz | C13: Mr. | D13: David
... A72: Id71 | B72: Turner | C72: Mr. | D72: Jeff
A73: Id72 | B73: Rangel | C73: Mr. | D73: Elenilton V | E73: Sr.
A74: Id73 | B74: Lacey | C74: Ms. | D74: Maurya
A75: Id74 | B75: Stiger | C75: Ms. | D75: Samantha C
A76: Id75 | B76: Caldwell | C76: Ms. | D76: Bethany A
A77: Id76 | B77: Marmillod | C77: Mr. | D77: Yves
A78: Id77 | B78: Cloutier-Simons | C78: Ms. | D78: Danielle
A79: Id78 | B79: Vegas | C79: Ms. | D79: Julia
A80: Id79 | B80: Cochran | C80: Mr. | D80: Joshua
A81: Id80 | B81: Holtzapple | C81: Ms. | D81: Jennifer
A82: Id81 | B82: Meyer | C82: Ms. | D82: Gwen M
A83: Id82 | B83: Brickley | C83: Mr. | D83: Patrick
A84: Id83 | B84: Magee | C84: Ms. | D84: Kate
A85: Id84 | B85: Thoma | C85: Mr. | D85: Kevin
... A725: Id724 | B725: Nemec | C725: Mrs. | D725: Lisa
A726: Id725 | B726: Appman | C726: Mr. | D726: William D | E726: Jr.
A727: Id726 | B727: Driscoll | C727: Mr. | D727: James
A728: Id727 | B728: Glotzbach | C728: Mr. | D728: John
A729: Id728 | B729: Tenforde | C729: Mr. | D729: Adam S
A730: Id729 | B730: Ramirez | C730: Mr. | D730: Armando
A731: Id730 | B731: Stanley Torres | C731: Ms. | D731: Dana
A732: Id731 | B732: Vandongen | C732: Ms. | D732: Jennifer L
A733: Id732 | B733: Liebald | C733: Mr. | D733: Benjamin
A734: Id733 | B734: Holte | C734: Ms. | D734: Tanya
A735: Id734 | B735: Johnson | C735: Ms. | D735: Tracy
A736: Id735 | B736: Bartlett | C736: Ms. | D736: Emily S
A737: Id736 | B737: Bergman | C737: Ms. | D737: Kelly R
...

Sheet Dashboard

Sheet Pivot Table
A3: Row Labels | B3: Count of Smoker | D3: Row Labels | E3: Sum of Number of Major Surgeries | F3: Average of HBA1C
A4: No | B4: 1944 | D4: No | E4: 1417 | F4: 6.6608854
A5: Yes | B5: 391 | D5: yes | E5: 162 | F5: 5.1736111
A6: Grand Total | B6: 2335 | D6: Grand Total | E6: 1579 | F6: 6.5691649
A9: Average of Charges | B9: Column Labels | G9: Row Labels | H9: Average of Charges
A10: Row Labels | B10: Diabetes | C10: Normal | D10: Prediabetes | E10: Grand Total | G10: tier - 1 | H10: 29767.395
A11: Normal Weight | B11: 13632.37 | C11: 13428.632 | D11: 14795.963 | E11: 13862.332 | G11: tier - 2 | H11: 11807.332
A12: Obesity | B12: 14198.297 | C12: 10373.867 | D12: 18338.19 | E12: 13691.353 | G12: tier - 3 | H12: 9450.2781
A13: Overweight | B13: 13680.799 | C13: 12072.498 | D13: 13518.559 | E13: 12955.969 | G13: Unknown | H13: 700
A14: Underweight | B14: 14268.758 | C14: 8884.4459 | D14: 16449.368 | E14: 12495.86 | G14: Grand Total | H14: 13478.748
A15: Grand Total | B15: 14023.435 | C15: 11141.377 | D15: 16450.772 | E15: 13478.748

Sheet Hospitalisation Details
A1: Customer ID | B1: year | C1: month | D1: date | E1: children | F1: charges | G1: Hospital tier | H1: City tier | I1: State ID | J1: Date of Birth | K1: Age
A2: Id2285 | B2: 2004 | C2: Jun | D2: 10 | E2: 0 | F2: 1147 | G2: tier - 2 | H2: tier - 2 | I2: R1013 | J2: =CONCATENATE(D2," ",C2," ",B2) -> 10 Jun 2004 | K2: =DATEDIF(J2,DATE(2023,6,8),"Y") -> 18
A3: Id2283 | B3: 2004 | C3: Jul | D3: 18 | E3: 0 | F3: 1149 | G3: tier - 2 | H3: tier - 2 | I3: R1013 | J3: =CONCATENATE(D3," ",C3," ",B3) -> 18 Jul 2004 | K3: =DATEDIF(J3,DATE(2023,6,8),"Y") -> 18
A4: Id2277 | B4: 1997 | C4: Jun | D4: 28 | E4: 0 | F4: 1178 | G4: tier - 2 | H4: tier - 2 | I4: R1013 | J4: =CONCATENATE(D4," ",C4," ",B4) -> 28 Jun 1997 | K4: =DATEDIF(J4,DATE(2023,6,8),"Y") -> 25
A5: Id2268 | B5: 2002 | C5: Dec | D5: 12 | E5: 0 | F5: 1237 | G5: tier - 2 | H5: tier - 2 | I5: R1013 | J5: =CONCATENATE(D5," ",C5," ",B5) -> 12 Dec 2002 | K5: =DATEDIF(J5,DATE(2023,6,8),"Y") -> 20
A6: Id2266 | B6: 2002 | C6: Jul | D6: 1 | E6: 0 | F6: 1241 | G6: tier - 2 | H6: tier - 2 | I6: R1013 | J6: =CONCATENATE(D6," ",C6," ",B6) -> 1 Jul 2002 | K6: =DATEDIF(J6,DATE(2023,6,8),"Y") -> 20
A7: Id2261 | B7: 1997 | C7: Nov | D7: 4 | E7: 0 | F7: 1253 | G7: tier - 2 | H7: tier - 2 | I7: R1013 | J7: =CONCATENATE(D7," ",C7," ",B7) -> 4 Nov 1997 | K7: =DATEDIF(J7,DATE(2023,6,8),"Y") -> 25
A8: Id2251 | B8: 2000 | C8: Jun | D8: 26 | E8: 0 | F8: 1286 | G8: tier - 2 | H8: tier - 2 | I8: R1013 | J8: =CONCATENATE(D8," ",C8," ",B8) -> 26 Jun 2000 | K8: =DATEDIF(J8,DATE(2023,6,8),"Y") -> 22 | N8: AVERAGE | O8: =ROUND(AVERAGE(Hospitalisation_Details[year]),0) -> 1983
A9: Id2250 | B9: 1998 | C9: Jun | D9: 4 | E9: 0 | F9: 1291 | G9: tier - 2 | H9: tier - 2 | I9: R1013 | J9: =CONCATENATE(D9," ",C9," ",B9) -> 4 Jun 1998 | K9: =DATEDIF(J9,DATE(2023,6,8),"Y") -> 25
A10: Id2247 | B10: 1999 | C10: Dec | D10: 2 | E10: 0 | F10: 1304 | G10: tier - 2 | H10: tier - 2 | I10: R1013 | J10: =CONCATENATE(D10," ",C10," ",B10) -> 2 Dec 1999 | K10: =DATEDIF(J10,DATE(2023,6,8),"Y") -> 23 | N10: AVERAGE IF | O10: =AVERAGEIF(Hospitalisation_Details[date],">0",Hospitalisation_Details[year]) -> 1982.8415
A11: Id2246 | B11: 2002 | C11: Oct | D11: 13 | E11: 0 | F11: 1315 | G11: tier - 2 | H11: tier - 2 | I11: R1013 | J11: =CONCATENATE(D11," ",C11," ",B11) -> 13 Oct 2002 | K11: =DATEDIF(J11,DATE(2023,6,8),"Y") -> 20
A12: Id2239 | B12: 1999 | C12: Jul | D12: 6 | E12: 0 | F12: 1389 | G12: tier - 2 | H12: tier - 2 | I12: R1013 | J12: =CONCATENATE(D12," ",C12," ",B12) -> 6 Jul 1999 | K12: =DATEDIF(J12,DATE(2023,6,8),"Y") -> 23
A13: Id2238 | B13: 2002 | C13: Nov | D13: 14 | E13: 0 | F13: 1390 | G13: tier - 2 | H13: tier - 2 | I13: R1013 | J13: =CONCATENATE(D13," ",C13," ",B13) -> 14 Nov 2002 | K13: =DATEDIF(J13,DATE(2023,6,8),"Y") -> 20 | N13: MODE | O13: {=INDEX(Hospitalisation_Details[Hospital tier],_xlfn.MODE.SNGL(MATCH(Hospitalisation_Details[Hospital tier],Hospitalisation_Details[Hospital tier],0)))} -> tier - 2
A14: Id2236 | B14: 1998 | C14: Sep | D14: 5 | E14: 0 | F14: 1400 | G14: tier - 2 | H14: tier - 2 | I14: R1013 | J14: =CONCATENATE(D14," ",C14," ",B14) -> 5 Sep 1998 | K14: =DATEDIF(J14,DATE(2023,6,8),"Y") -> 24
A15: Id2233 | B15: 2001 | C15: Aug | D15: 23 | E15: 0 | F15: 1421 | G15: tier - 2 | H15: tier - 2 | I15: R1013 | J15: =CONCATENATE(D15," ",C15," ",B15) -> 23 Aug 2001 | K15: =DATEDIF(J15,DATE(2023,6,8),"Y") -> 21
A16: Id2232 | B16: 1997 | C16: Dec | D16: 5 | E16: 0 | F16: 1422 | G16: tier - 2 | H16: tier - 2 | I16: R1013 | J16: =CONCATENATE(D16," ",C16," ",B16) -> 5 Dec 1997 | K16: =DATEDIF(J16,DATE(2023,6,8),"Y") -> 25
A17: Id2231 | B17: 2000 | C17: Sep | D17: 1 | E17: 0 | F17: 1438 | G17: tier - 2 | H17: tier - 2 | I17: R1013 | J17: =CONCATENATE(D17," ",C17," ",B17) -> 1 Sep 2000 | K17: =DATEDIF(J17,DATE(2023,6,8),"Y") -> 22
A18: Id2229 | B18: 2003 | C18: Jun | D18: 20 | E18: 0 | F18: 1467 | G18: tier - 2 | H18: tier - 2 | I18: R1013 | J18: =CONCATENATE(D18," ",C18," ",B18) -> 20 Jun 2003 | K18: =DATEDIF(J18,DATE(2023,6,8),"Y") -> 19
A19: Id2225 | B19: 1998 | C19: Jun | D19: 19 | E19: 0 | F19: 1497 | G19: tier - 2 | H19: tier - 2 | I19: R1013 | J19: =CONCATENATE(D19," ",C19," ",B19) -> 19 Jun 1998 | K19: =DATEDIF(J19,DATE(2023,6,8),"Y") -> 24
A20: Id2222 | B20: 2001 | C20: Jun | D20: 2 | E20: 0 | F20: 1532 | G20: tier - 2 | H20: tier - 2 | I20: R1013 | J20: =CONCATENATE(D20," ",C20," ",B20) -> 2 Jun 2001 | K20: =DATEDIF(J20,DATE(2023,6,8),"Y") -> 22
A21: Id2221 | B21: 2001 | C21: Dec | D21: 5 | E21: 0 | F21: 1534 | G21: tier - 2 | H21: tier - 2 | I21: R1013 | J21: =CONCATENATE(D21," ",C21," ",B21) -> 5 Dec 2001 | K21: =DATEDIF(J21,DATE(2023,6,8),"Y") -> 21
A22: Id2215 | B22: 2004 | C22: Aug | D22: 21 | E22: 0 | F22: 1622 | G22: tier - 2 | H22: tier - 2 | I22: R1013 | J22: =CONCATENATE(D22," ",C22," ",B22) -> 21 Aug 2004 | K22: =DATEDIF(J22,DATE(2023,6,8),"Y") -> 18
A23: Id2210 | B23: 2004 | C23: Oct | D23: 4 | E23: 0 | F23: 1630 | G23: tier - 2 | H23: tier - 2 | I23: R1013 | J23: =CONCATENATE(D23," ",C23," ",B23) -> 4 Oct 2004 | K23: =DATEDIF(J23,DATE(2023,6,8),"Y") -> 18
A24: Id2205 | B24: 2004 | C24: Dec | D24: 13 | E24: 0 | F24: 1633 | G24: tier - 2 | H24: tier - 2 | I24: R1013 | J24: =CONCATENATE(D24," ",C24," ",B24) -> 13 Dec 2004 | K24: =DATEDIF(J24,DATE(2023,6,8),"Y") -> 18
A25: Id2203 | B25: 2004 | C25: Jun | D25: 13 | E25: 0 | F25: 1635 | G25: tier - 2 | H25: tier - 2 | I25: R1013 | J25: =CONCATENATE(D25," ",C25," ",B25) -> 13 Jun 2004 | K25: =DATEDIF(J25,DATE(2023,6,8),"Y") -> 18
... A2342: Id210 | B2342: 2000 | C2342: Dec | D2342: 17 | E2342: 3 | F2342: 35596 | G2342: tier - 2 | H2342: tier - 3 | I2342: R1013 | J2342: =CONCATENATE(D2342," ",C2342," ",B2342) -> 17 Dec 2000 | K2342: =DATEDIF(J2342,DATE(2023,6,8),"Y") -> 22

Sheet Medical Examinations
A1: Customer ID | B1: BMI | C1: HBA1C | D1: Heart Issues | E1: Proper Function | F1: Any Transplants | G1: Cancer history | H1: NumberOfMajorSurgeries | I1: smoker | J1: Proper Function2 | K1: Weight Status | L1: Diabetes Status
A2: Id413 | B2: 38 | C2: 5 | D2: No | E2: =PROPER(Medical_Examinations[[#This Row],[Heart Issues]]) -> No | F2: No | G2: No | H2: 1 | I2: No | J2: =PROPER(Medical_Examinations[[#This Row],[smoker]]) -> No | K2: =IF(B2<18.5,"Underweight",IF(B2<25,"Normal Weight",IF(B2<30,"Overweight","Obesity"))) -> Obesity | L2: =IF(C2<5.7,"Normal",IF(C2<6.5,"Prediabetes","Diabetes")) -> Normal
A3: Id432 | B3: 31 | C3: 5 | D3: No | E3: =PROPER(Medical_Examinations[[#This Row],[Heart Issues]]) -> No | F3: No | G3: Yes | H3: 1 | I3: No | J3: =PROPER(Medical_Examinations[[#This Row],[smoker]]) -> No | K3: =IF(B3<18.5,"Underweight",IF(B3<25,"Normal Weight",IF(B3<30,"Overweight","Obesity"))) -> Obesity | L3: =IF(C3<5.7,"Normal",IF(C3<6.5,"Prediabetes","Diabetes")) -> Normal
A4: Id489 | B4: 30 | C4: 5 | D4: No | E4: =PROPER(Medical_Examinations[[#This Row],[Heart Issues]]) -> No | F4: No | G4: Yes | H4: 1 | I4: No | J4: =PROPER(Medical_Examinations[[#This Row],[smoker]]) -> No | K4: =IF(B4<18.5,"Underweight",IF(B4<25,"Normal Weight",IF(B4<30,"Overweight","Obesity"))) -> Obesity | L4: =IF(C4<5.7,"Normal",IF(C4<6.5,"Prediabetes","Diabetes")) -> Normal
A5: Id510 | B5: 33 | C5: 5 | D5: No | E5: =PROPER(Medical_Examinations[[#This Row],[Heart Issues]]) -> No | F5: No | G5: Yes | H5: 1 | I5: No | J5: =PROPER(Medical_Examinations[[#This Row],[smoker]]) -> No | K5: =IF(B5<18.5,"Underweight",IF(B5<25,"Normal Weight",IF(B5<30,"Overweight","Obesity"))) -> Obesity | L5: =IF(C5<5.7,"Normal",IF(C5<6.5,"Prediabetes","Diabetes")) -> Normal
A6: Id523 | B6: 28 | C6: 5 | D6: No | E6: =PROPER(Medical_Examinations[[#This Row],[Heart Issues]]) -> No | F6: No | G6: No | H6: 1 | I6: No | J6: =PROPER(Medical_Examinations[[#This Row],[smoker]]) -> No | K6: =IF(B6<18.5,"Underweight",IF(B6<25,"Normal Weight",IF(B6<30,"Overweight","Obesity"))) -> Overweight | L6: =IF(C6<5.7,"Normal",IF(C6<6.5,"Prediabetes","Diabetes")) -> Normal
A7: Id528 | B7: 28 | C7: 5 | D7: No | E7: =PROPER(Medical_Examinations[[#This Row],[Heart Issues]]) -> No | F7: No | G7: Yes | H7: 1 | I7: No | J7: =PROPER(Medical_Examinations[[#This Row],[smoker]]) -> No | K7: =IF(B7<18.5,"Underweight",IF(B7<25,"Normal Weight",IF(B7<30,"Overweight","Obesity"))) -> Overweight | L7: =IF(C7<5.7,"Normal",IF(C7<6.5,"Prediabetes","Diabetes")) -> Normal
A8: Id546 | B8: 30 | C8: 5 | D8: No | E8: =PROPER(Medical_Examinations[[#This Row],[Heart Issues]]) -> No | F8: No | G8: Yes | H8: 1 | I8: No | J8: =PROPER(Medical_Examinations[[#This Row],[smoker]]) -> No | K8: =IF(B8<18.5,"Underweight",IF(B8<25,"Normal Weight",IF(B8<30,"Overweight","Obesity"))) -> Obesity | L8: =IF(C8<5.7,"Normal",IF(C8<6.5,"Prediabetes","Diabetes")) -> Normal
A9: Id553 | B9: 54 | C9: 5 | D9: No | E9: =PROPER(Medical_Examinations[[#This Row],[Heart Issues]]) -> No | F9: No | G9: Yes | H9: 1 | I9: No | J9: =PROPER(Medical_Examinations[[#This Row],[smoker]]) -> No | K9: =IF(B9<18.5,"Underweight",IF(B9<25,"Normal Weight",IF(B9<30,"Overweight","Obesity"))) -> Obesity | L9: =IF(C9<5.7,"Normal",IF(C9<6.5,"Prediabetes","Diabetes")) -> Normal
A10: Id612 | B10: 55 | C10: 5 | D10: No | E10: =PROPER(Medical_Examinations[[#This Row],[Heart Issues]]) -> No | F10: No | G10: No | H10: 1 | I10: No | J10: =PROPER(Medical_Examinations[[#This Row],[smoker]]) -> No | K10: =IF(B10<18.5,"Underweight",IF(B10<25,"Normal Weight",IF(B10<30,"Overweight","Obesity"))) -> Obesity | L10: =IF(C10<5.7,"Normal",IF(C10<6.5,"Prediabetes","Diabetes")) -> Normal
A11: Id658 | B11: 47 | C11: 5 | D11: No | E11: =PROPER(Medical_Examinations[[#This Row],[Heart Issues]]) -> No | F11: No | G11: Yes | H11: 1 | I11: No | J11: =PROPER(Medical_Examinations[[#This Row],[smoker]]) -> No | K11: =IF(B11<18.5,"Underweight",IF(B11<25,"Normal Weight",IF(B11<30,"Overweight","Obesity"))) -> Obesity | L11: =IF(C11<5.7,"Normal",IF(C11<6.5,"Prediabetes","Diabetes")) -> Normal
A12: Id754 | B12: 54 | C12: 5 | D12: No | E12: =PROPER(Medical_Examinations[[#This Row],[Heart Issues]]) -> No | F12: No | G12: No | H12: 1 | I12: No | J12: =PROPER(Medical_Examinations[[#This Row],[smoker]]) -> No | K12: =IF(B12<18.5,"Underweight",IF(B12<25,"Normal Weight",IF(B12<30,"Overweight","Obesity"))) -> Obesity | L12: =IF(C12<5.7,"Normal",IF(C12<6.5,"Prediabetes","Diabetes")) -> Normal
A13: Id775 | B13: 42 | C13: 5 | D13: No | E13: =PROPER(Medical_Examinations[[#This Row],[Heart Issues]]) -> No | F13: No | G13: No | H13: 1 | I13: No | J13: =PROPER(Medical_Examinations[[#This Row],[smoker]]) -> No | K13: =IF(B13<18.5,"Underweight",IF(B13<25,"Normal Weight",IF(B13<30,"Overweight","Obesity"))) -> Obesity | L13: =IF(C13<5.7,"Normal",IF(C13<6.5,"Prediabetes","Diabetes")) -> Normal
A14: Id820 | B14: 41 | C14: 5 | D14: No | E14: =PROPER(Medical_Examinations[[#This Row],[Heart Issues]]) -> No | F14: No | G14: No | H14: 1 | I14: No | J14: =PROPER(Medical_Examinations[[#This Row],[smoker]]) -> No | K14: =IF(B14<18.5,"Underweight",IF(B14<25,"Normal Weight",IF(B14<30,"Overweight","Obesity"))) -> Obesity | L14: =IF(C14<5.7,"Normal",IF(C14<6.5,"Prediabetes","Diabetes")) -> Normal | N14: No of major surgeries convert to Numerical values =0
A15: Id823 | B15: 53 | C15: 5 | D15: No | E15: =PROPER(Medical_Examinations[[#This Row],[Heart Issues]]) -> No | F15: No | G15: Yes | H15: 1 | I15: No | J15: =PROPER(Medical_Examinations[[#This Row],[smoker]]) -> No | K15: =IF(B15<18.5,"Underweight",IF(B15<25,"Normal Weight",IF(B15<30,"Overweight","Obesity"))) -> Obesity | L15: =IF(C15<5.7,"Normal",IF(C15<6.5,"Prediabetes","Diabetes")) -> Normal
A16: Id849 | B16: 27 | C16: 5 | D16: No | E16: =PROPER(Medical_Examinations[[#This Row],[Heart Issues]]) -> No | F16: No | G16: No | H16: 1 | I16: No | J16: =PROPER(Medical_Examinations[[#This Row],[smoker]]) -> No | K16: =IF(B16<18.5,"Underweight",IF(B16<25,"Normal Weight",IF(B16<30,"Overweight","Obesity"))) -> Overweight | L16: =IF(C16<5.7,"Normal",IF(C16<6.5,"Prediabetes","Diabetes")) -> Normal
A17: Id863 | B17: 37 | C17: 5 | D17: No | E17: =PROPER(Medical_Examinations[[#This Row],[Heart Issues]]) -> No | F17: No | G17: Yes | H17: 1 | I17: No | J17: =PROPER(Medical_Examinations[[#This Row],[smoker]]) -> No | K17: =IF(B17<18.5,"Underweight",IF(B17<25,"Normal Weight",IF(B17<30,"Overweight","Obesity"))) -> Obesity | L17: =IF(C17<5.7,"Normal",IF(C17<6.5,"Prediabetes","Diabetes")) -> Normal
A18: Id906 | B18: 50 | C18: 5 | D18: No | E18: =PROPER(Medical_Examinations[[#This Row],[Heart Issues]]) -> No | F18: No | G18: Yes | H18: 1 | I18: No | J18: =PROPER(Medical_Examinations[[#This Row],[smoker]]) -> No | K18: =IF(B18<18.5,"Underweight",IF(B18<25,"Normal Weight",IF(B18<30,"Overweight","Obesity"))) -> Obesity | L18: =IF(C18<5.7,"Normal",IF(C18<6.5,"Prediabetes","Diabetes")) -> Normal
A19: Id1147 | B19: 43 | C19: 5 | D19: No | E19: =PROPER(Medical_Examinations[[#This Row],[Heart Issues]]) -> No | F19: No | G19: No | H19: 1 | I19: No | J19: =PROPER(Medical_Examinations[[#This Row],[smoker]]) -> No | K19: =IF(B19<18.5,"Underweight",IF(B19<25,"Normal Weight",IF(B19<30,"Overweight","Obesity"))) -> Obesity | L19: =IF(C19<5.7,"Normal",IF(C19<6.5,"Prediabetes","Diabetes")) -> Normal
A20: Id1171 | B20: 45 | C20: 5 | D20: No | E20: =PROPER(Medical_Examinations[[#This Row],[Heart Issues]]) -> No | F20: No | G20: No | H20: 1 | I20: No | J20: =PROPER(Medical_Examinations[[#This Row],[smoker]]) -> No | K20: =IF(B20<18.5,"Underweight",IF(B20<25,"Normal Weight",IF(B20<30,"Overweight","Obesity"))) -> Obesity | L20: =IF(C20<5.7,"Normal",IF(C20<6.5,"Prediabetes","Diabetes")) -> Normal
A21: Id1187 | B21: 42 | C21: 5 | D21: No | E21: =PROPER(Medical_Examinations[[#This Row],[Heart Issues]]) -> No | F21: No | G21: No | H21: 1 | I21: No | J21: =PROPER(Medical_Examinations[[#This Row],[smoker]]) -> No | K21: =IF(B21<18.5,"Underweight",IF(B21<25,"Normal Weight",IF(B21<30,"Overweight","Obesity"))) -> Obesity | L21: =IF(C21<5.7,"Normal",IF(C21<6.5,"Prediabetes","Diabetes")) -> Normal
A22: Id1192 | B22: 33 | C22: 5 | D22: No | E22: =PROPER(Medical_Examinations[[#This Row],[Heart Issues]]) -> No | F22: No | G22: No | H22: 1 | I22: No | J22: =PROPER(Medical_Examinations[[#This Row],[smoker]]) -> No | K22: =IF(B22<18.5,"Underweight",IF(B22<25,"Normal Weight",IF(B22<30,"Overweight","Obesity"))) -> Obesity | L22: =IF(C22<5.7,"Normal",IF(C22<6.5,"Prediabetes","Diabetes")) -> Normal
A23: Id1291 | B23: 34 | C23: 5 | D23: No | E23: =PROPER(Medical_Examinations[[#This Row],[Heart Issues]]) -> No | F23: No | G23: Yes | H23: 1 | I23: No | J23: =PROPER(Medical_Examinations[[#This Row],[smoker]]) -> No | K23: =IF(B23<18.5,"Underweight",IF(B23<25,"Normal Weight",IF(B23<30,"Overweight","Obesity"))) -> Obesity | L23: =IF(C23<5.7,"Normal",IF(C23<6.5,"Prediabetes","Diabetes")) -> Normal
A24: Id1313 | B24: 39 | C24: 5 | D24: No | E24: =PROPER(Medical_Examinations[[#This Row],[Heart Issues]]) -> No | F24: No | G24: Yes | H24: 1 | I24: No | J24: =PROPER(Medical_Examinations[[#This Row],[smoker]]) -> No | K24: =IF(B24<18.5,"Underweight",IF(B24<25,"Normal Weight",IF(B24<30,"Overweight","Obesity"))) -> Obesity | L24: =IF(C24<5.7,"Normal",IF(C24<6.5,"Prediabetes","Diabetes")) -> Normal
A25: Id1314 | B25: 31 | C25: 5 | D25: No | E25: =PROPER(Medical_Examinations[[#This Row],[Heart Issues]]) -> No | F25: No | G25: Yes | H25: 1 | I25: No | J25: =PROPER(Medical_Examinations[[#This Row],[smoker]]) -> No | K25: =IF(B25<18.5,"Underweight",IF(B25<25,"Normal Weight",IF(B25<30,"Overweight","Obesity"))) -> Obesity | L25: =IF(C25<5.7,"Normal",IF(C25<6.5,"Prediabetes","Diabetes")) -> Normal
A26: Id1343 | B26: 37 | C26: 5 | D26: No | E26: =PROPER(Medical_Examinations[[#This Row],[Heart Issues]]) -> No | F26: No | G26: Yes | H26: 1 | I26: No | J26: =PROPER(Medical_Examinations[[#This Row],[smoker]]) -> No | K26: =IF(B26<18.5,"Underweight",IF(B26<25,"Normal Weight",IF(B26<30,"Overweight","Obesity"))) -> Obesity | L26: =IF(C26<5.7,"Normal",IF(C26<6.5,"Prediabetes","Diabetes")) -> Normal
... A2336: Id635 | B2336: 25 | C2336: 5 | D2336: No | E2336: =PROPER(Medical_Examinations[[#This Row],[Heart Issues]]) -> No | F2336: yes | G2336: No | H2336: 1 | I2336: Unknown | J2336: =PROPER(Medical_Examinations[[#This Row],[smoker]]) -> Unknown | K2336: =IF(B2336<18.5,"Underweight",IF(B2336<25,"Normal Weight",IF(B2336<30,"Overweight","Obesity"))) -> Overweight | L2336: =IF(C2336<5.7,"Normal",IF(C2336<6.5,"Prediabetes","Diabetes")) -> Normal

Sheet Healthcare
A1: Customer ID | B1: First Name | C1: BMI | D1: HBA1C | E1: Heart Issues | F1: Any Transplants | G1: Cancer History | H1: Number of Major Surgeries | I1: Smoker | J1: Weight Status | K1: Diabetes Status | L1: Date of Birth | M1: Charges | N1: Hospital tier | O1: City tier | P1: State ID | Q1: Age
A2: Id1 | B2: =VLOOKUP(Customer_Names[[#This Row],[Customer ID]],Customer_Names[#All],2,FALSE) -> Hawks | C2: =VLOOKUP(Medical_Examinations[[#This Row],[Customer ID]],'Medical Examinations'!$A$1:$L$2336,2,FALSE) -> 38 | D2: =VLOOKUP(Medical_Examinations[[#This Row],[Customer ID]],'Medical Examinations'!$A$1:$L$2336,3,FALSE) -> 5 | E2: =VLOOKUP(Medical_Examinations[[#This Row],[Customer ID]],'Medical Examinations'!$A$1:$L$2336,4,FALSE) -> No | F2: =VLOOKUP(Medical_Examinations[[#This Row],[Customer ID]],'Medical Examinations'!$A$1:$L$2336,6,FALSE) -> No | G2: =VLOOKUP(Medical_Examinations[[#This Row],[Customer ID]],'Medical Examinations'!$A$1:$L$2336,7,FALSE) -> No | H2: =VLOOKUP(Medical_Examinations[[#This Row],[Customer ID]],'Medical Examinations'!$A$1:$L$2336,8,FALSE) -> 1 | I2: =VLOOKUP(Medical_Examinations[[#This Row],[Customer ID]],'Medical Examinations'!$A$1:$L$2336,9,FALSE) -> No | J2: =VLOOKUP(Medical_Examinations[[#This Row],[Customer ID]],'Medical Examinations'!A1:L2336,11,FALSE) -> Obesity | K2: =VLOOKUP(Medical_Examinations[[#This Row],[Customer ID]],'Medical Examinations'!A1:L2336,12,FALSE) -> Normal | L2: =VLOOKUP(Hospitalisation_Details[[#This Row],[Customer ID]],'Hospitalisation Details'!A1:K2342,10,FALSE) -> 10 Jun 2004 | M2: =VLOOKUP(Hospitalisation_Details[[#This Row],[Customer ID]],'Hospitalisation Details'!$A$1:$K$2342,6,FALSE) -> 1147 | N2: =VLOOKUP(Hospitalisation_Details[[#This Row],[Customer ID]],'Hospitalisation Details'!A1:K2342,7,FALSE) -> tier - 2 | O2: =VLOOKUP(Hospitalisation_Details[[#This Row],[Customer ID]],'Hospitalisation Details'!A1:K2342,8,FALSE) -> tier - 2 | P2: =VLOOKUP(Hospitalisation_Details[[#This Row],[Customer ID]],'Hospitalisation Details'!A1:K2342,9,FALSE) -> R1013 | Q2: =VLOOKUP(Hospitalisation_Details[[#This Row],[Customer ID]],'Hospitalisation Details'!$A$1:$K$2342,11,FALSE) -> 18
A3: Id2 | B3: =VLOOKUP(Customer_Names[[#This Row],[Customer ID]],Customer_Names[#All],2,FALSE) -> Lehner | C3: =VLOOKUP(Medical_Examinations[[#This Row],[Customer ID]],'Medical Examinations'!$A$1:$L$2336,2,FALSE) -> 31 | D3: =VLOOKUP(Medical_Examinations[[#This Row],[Customer ID]],'Medical Examinations'!$A$1:$L$2336,3,FALSE) -> 5 | E3: =VLOOKUP(Medical_Examinations[[#This Row],[Customer ID]],'Medical Examinations'!$A$1:$L$2336,4,FALSE) -> No | F3: =VLOOKUP(Medical_Examinations[[#This Row],[Customer ID]],'Medical Examinations'!$A$1:$L$2336,6,FALSE) -> No | G3: =VLOOKUP(Medical_Examinations[[#This Row],[Customer ID]],'Medical Examinations'!$A$1:$L$2336,7,FALSE) -> Yes | H3: =VLOOKUP(Medical_Examinations[[#This Row],[Customer ID]],'Medical Examinations'!$A$1:$L$2336,8,FALSE) -> 1 | I3: =VLOOKUP(Medical_Examinations[[#This Row],[Customer ID]],'Medical Examinations'!$A$1:$L$2336,9,FALSE) -> No | J3: =VLOOKUP(Medical_Examinations[[#This Row],[Customer ID]],'Medical Examinations'!A2:L2337,11,FALSE) -> Obesity | K3: =VLOOKUP(Medical_Examinations[[#This Row],[Customer ID]],'Medical Examinations'!A2:L2337,12,FALSE) -> Normal | L3: =VLOOKUP(Hospitalisation_Details[[#This Row],[Customer ID]],'Hospitalisation Details'!A2:K2343,10,FALSE) -> 18 Jul 2004 | M3: =VLOOKUP(Hospitalisation_Details[[#This Row],[Customer ID]],'Hospitalisation Details'!$A$1:$K$2342,6,FALSE) -> 1149 | N3: =VLOOKUP(Hospitalisation_Details[[#This Row],[Customer ID]],'Hospitalisation Details'!A2:K2343,7,FALSE) -> tier - 2 | O3: =VLOOKUP(Hospitalisation_Details[[#This Row],[Customer ID]],'Hospitalisation Details'!A2:K2343,8,FALSE) -> tier - 2 | P3: =VLOOKUP(Hospitalisation_Details[[#This Row],[Customer ID]],'Hospitalisation Details'!A2:K2343,9,FALSE) -> R1013 | Q3: =VLOOKUP(Hospitalisation_Details[[#This Row],[Customer ID]],'Hospitalisation Details'!$A$1:$K$2342,11,FALSE) -> 18
A4: Id3 | B4: =VLOOKUP(Customer_Names[[#This Row],[Customer ID]],Customer_Names[#All],2,FALSE) -> Lu | C4: =VLOOKUP(Medical_Examinations[[#This Row],[Customer ID]],'Medical Examinations'!$A$1:$L$2336,2,FALSE) -> 30 | D4: =VLOOKUP(Medical_Examinations[[#This Row],[Customer ID]],'Medical Examinations'!$A$1:$L$2336,3,FALSE) -> 5 | E4: =VLOOKUP(Medical_Examinations[[#This Row],[Customer ID]],'Medical Examinations'!$A$1:$L$2336,4,FALSE) -> No | F4: =VLOOKUP(Medical_Examinations[[#This Row],[Customer ID]],'Medical Examinations'!$A$1:$L$2336,6,FALSE) -> No | G4: =VLOOKUP(Medical_Examinations[[#This Row],[Customer ID]],'Medical Examinations'!$A$1:$L$2336,7,FALSE) -> Yes | H4: =VLOOKUP(Medical_Examinations[[#This Row],[Customer ID]],'Medical Examinations'!$A$1:$L$2336,8,FALSE) -> 1 | I4: =VLOOKUP(Medical_Examinations[[#This Row],[Customer ID]],'Medical Examinations'!$A$1:$L$2336,9,FALSE) -> No | J4: =VLOOKUP(Medical_Examinations[[#This Row],[Customer ID]],'Medical Examinations'!A3:L2338,11,FALSE) -> Obesity | K4: =VLOOKUP(Medical_Examinations[[#This Row],[Customer ID]],'Medical Examinations'!A3:L2338,12,FALSE) -> Normal | L4: =VLOOKUP(Hospitalisation_Details[[#This Row],[Customer ID]],'Hospitalisation Details'!A3:K2344,10,FALSE) -> 28 Jun 1997 | M4: =VLOOKUP(Hospitalisation_Details[[#This Row],[Customer ID]],'Hospitalisation Details'!$A$1:$K$2342,6,FALSE) -> 1178 | N4: =VLOOKUP(Hospitalisation_Details[[#This Row],[Customer ID]],'Hospitalisation Details'!A3:K2344,7,FALSE) -> tier - 2 | O4: =VLOOKUP(Hospitalisation_Details[[#This Row],[Customer ID]],'Hospitalisation Details'!A3:K2344,8,FALSE) -> tier - 2 | P4: =VLOOKUP(Hospitalisation_Details[[#This Row],[Customer ID]],'Hospitalisation Details'!A3:K2344,9,FALSE) -> R1013 | Q4: =VLOOKUP(Hospitalisation_Details[[#This Row],[Customer ID]],'Hospitalisation Details'!$A$1:$K$2342,11,FALSE) -> 25
A5: Id4 | B5: =VLOOKUP(Customer_Names[[#This Row],[Customer ID]],Customer_Names[#All],2,FALSE) -> Osborne | C5: =VLOOKUP(Medical_Examinations[[#This Row],[Customer ID]],'Medical Examinations'!$A$1:$L$2336,2,FALSE) -> 33 | D5: =VLOOKUP(Medical_Examinations[[#This Row],[Customer ID]],'Medical Examinations'!$A$1:$L$2336,3,FALSE) -> 5 | E5: =VLOOKUP(Medical_Examinations[[#This Row],[Customer ID]],'Medical Examinations'!$A$1:$L$2336,4,FALSE) -> No | F5: =VLOOKUP(Medical_Examinations[[#This Row],[Customer ID]],'Medical Examinations'!$A$1:$L$2336,6,FALSE) -> No | G5: =VLOOKUP(Medical_Examinations[[#This Row],[Customer ID]],'Medical Examinations'!$A$1:$L$2336,7,FALSE) -> Yes | H5: =VLOOKUP(Medical_Examinations[[#This Row],[Customer ID]],'Medical Examinations'!$A$1:$L$2336,8,FALSE) -> 1 | I5: =VLOOKUP(Medical_Examinations[[#This Row],[Customer ID]],'Medical Examinations'!$A$1:$L$2336,9,FALSE) -> No | J5: =VLOOKUP(Medical_Examinations[[#This Row],[Customer ID]],'Medical Examinations'!A4:L2339,11,FALSE) -> Obesity | K5: =VLOOKUP(Medical_Examinations[[#This Row],[Customer ID]],'Medical Examinations'!A4:L2339,12,FALSE) -> Normal | L5: =VLOOKUP(Hospitalisation_Details[[#This Row],[Customer ID]],'Hospitalisation Details'!A4:K2345,10,FALSE) -> 12 Dec 2002 | M5: =VLOOKUP(Hospitalisation_Details[[#This Row],[Customer ID]],'Hospitalisation Details'!$A$1:$K$2342,6,FALSE) -> 1237 | N5: =VLOOKUP(Hospitalisation_Details[[#This Row],[Customer ID]],'Hospitalisation Details'!A4:K2345,7,FALSE) -> tier - 2 | O5: =VLOOKUP(Hospitalisation_Details[[#This Row],[Customer ID]],'Hospitalisation Details'!A4:K2345,8,FALSE) -> tier - 2 | P5: =VLOOKUP(Hospitalisation_Details[[#This Row],[Customer ID]],'Hospitalisation Details'!A4:K2345,9,FALSE) -> R1013 | Q5: =VLOOKUP(Hospitalisation_Details[[#This Row],[Customer ID]],'Hospitalisation Details'!$A$1:$K$2342,11,FALSE) -> 20
A6: Id5 | B6: =VLOOKUP(Customer_Names[[#This Row],[Customer ID]],Customer_Names[#All],2,FALSE) -> Kadala | C6: =VLOOKUP(Medical_Examinations[[#This Row],[Customer ID]],'Medical Examinations'!$A$1:$L$2336,2,FALSE) -> 28 | D6: =VLOOKUP(Medical_Examinations[[#This Row],[Customer ID]],'Medical Examinations'!$A$1:$L$2336,3,FALSE) -> 5 | E6: =VLOOKUP(Medical_Examinations[[#This Row],[Customer ID]],'Medical Examinations'!$A$1:$L$2336,4,FALSE) -> No | F6: =VLOOKUP(Medical_Examinations[[#This Row],[Customer ID]],'Medical Examinations'!$A$1:$L$2336,6,FALSE) -> No | G6: =VLOOKUP(Medical_Examinations[[#This Row],[Customer ID]],'Medical Examinations'!$A$1:$L$2336,7,FALSE) -> No | H6: =VLOOKUP(Medical_Examinations[[#This Row],[Customer ID]],'Medical Examinations'!$A$1:$L$2336,8,FALSE) -> 1 | I6: =VLOOKUP(Medical_Examinations[[#This Row],[Customer ID]],'Medical Examinations'!$A$1:$L$2336,9,FALSE) -> No | J6: =VLOOKUP(Medical_Examinations[[#This Row],[Customer ID]],'Medical Examinations'!A5:L2340,11,FALSE) -> Overweight | K6: =VLOOKUP(Medical_Examinations[[#This Row],[Customer ID]],'Medical Examinations'!A5:L2340,12,FALSE) -> Normal | L6: =VLOOKUP(Hospitalisation_Details[[#This Row],[Customer ID]],'Hospitalisation Details'!A5:K2346,10,FALSE) -> 1 Jul 2002 | M6: =VLOOKUP(Hospitalisation_Details[[#This Row],[Customer ID]],'Hospitalisation Details'!$A$1:$K$2342,6,FALSE) -> 1241 | N6: =VLOOKUP(Hospitalisation_Details[[#This Row],[Customer ID]],'Hospitalisation Details'!A5:K2346,7,FALSE) -> tier - 2 | O6: =VLOOKUP(Hospitalisation_Details[[#This Row],[Customer ID]],'Hospitalisation Details'!A5:K2346,8,FALSE) -> tier - 2 | P6: =VLOOKUP(Hospitalisation_Details[[#This Row],[Customer ID]],'Hospitalisation Details'!A5:K2346,9,FALSE) -> R1013 | Q6: =VLOOKUP(Hospitalisation_Details[[#This Row],[Customer ID]],'Hospitalisation Details'!$A$1:$K$2342,11,FALSE) -> 20
A7: Id6 | B7: =VLOOKUP(Customer_Names[[#This Row],[Customer ID]],Customer_Names[#All],2,FALSE) -> Baker | C7: =VLOOKUP(Medical_Examinations[[#This Row],[Customer ID]],'Medical Examinations'!$A$1:$L$2336,2,FALSE) -> 28 | D7: =VLOOKUP(Medical_Examinations[[#This Row],[Customer ID]],'Medical Examinations'!$A$1:$L$2336,3,FALSE) -> 5 | E7: =VLOOKUP(Medical_Examinations[[#This Row],[Customer ID]],'Medical Examinations'!$A$1:$L$2336,4,FALSE) -> No | F7: =VLOOKUP(Medical_Examinations[[#This Row],[Customer ID]],'Medical Examinations'!$A$1:$L$2336,6,FALSE) -> No | G7: =VLOOKUP(Medical_Examinations[[#This Row],[Customer ID]],'Medical Examinations'!$A$1:$L$2336,7,FALSE) -> Yes | H7: =VLOOKUP(Medical_Examinations[[#This Row],[Customer ID]],'Medical Examinations'!$A$1:$L$2336,8,FALSE) -> 1 | I7: =VLOOKUP(Medical_Examinations[[#This Row],[Customer ID]],'Medical Examinations'!$A$1:$L$2336,9,FALSE) -> No | J7: =VLOOKUP(Medical_Examinations[[#This Row],[Customer ID]],'Medical Examinations'!A6:L2341,11,FALSE) -> Overweight | K7: =VLOOKUP(Medical_Examinations[[#This Row],[Customer ID]],'Medical Examinations'!A6:L2341,12,FALSE) -> Normal | L7: =VLOOKUP(Hospitalisation_Details[[#This Row],[Customer ID]],'Hospitalisation Details'!A6:K2347,10,FALSE) -> 4 Nov 1997 | M7: =VLOOKUP(Hospitalisation_Details[[#This Row],[Customer ID]],'Hospitalisation Details'!$A$1:$K$2342,6,FALSE) -> 1253 | N7: =VLOOKUP(Hospitalisation_Details[[#This Row],[Customer ID]],'Hospitalisation Details'!A6:K2347,7,FALSE) -> tier - 2 | O7: =VLOOKUP(Hospitalisation_Details[[#This Row],[Customer ID]],'Hospitalisation Details'!A6:K2347,8,FALSE) -> tier - 2 | P7: =VLOOKUP(Hospitalisation_Details[[#This Row],[Customer ID]],'Hospitalisation Details'!$A$6:$K$2347,9,FALSE) -> R1013 | Q7: =VLOOKUP(Hospitalisation_Details[[#This Row],[Customer ID]],'Hospitalisation Details'!$A$1:$K$2342,11,FALSE) -> 25
A8: Id7 | B8: =VLOOKUP(Customer_Names[[#This Row],[Customer ID]],Customer_Names[#All],2,FALSE) -> Macpherson | C8: =VLOOKUP(Medical_Examinations[[#This Row],[Customer ID]],'Medical Examinations'!$A$1:$L$2336,2,FALSE) -> 30 | D8: =VLOOKUP(Medical_Examinations[[#This Row],[Customer ID]],'Medical Examinations'!$A$1:$L$2336,3,FALSE) -> 5 | E8: =VLOOKUP(Medical_Examinations[[#This Row],[Customer ID]],'Medical Examinations'!$A$1:$L$2336,4,FALSE) -> No | F8: =VLOOKUP(Medical_Examinations[[#This Row],[Customer ID]],'Medical Examinations'!$A$1:$L$2336,6,FALSE) -> No | G8: =VLOOKUP(Medical_Examinations[[#This Row],[Customer ID]],'Medical Examinations'!$A$1:$L$2336,7,FALSE) -> Yes | H8: =VLOOKUP(Medical_Examinations[[#This Row],[Customer ID]],'Medical Examinations'!$A$1:$L$2336,8,FALSE) -> 1 | I8: =VLOOKUP(Medical_Examinations[[#This Row],[Customer ID]],'Medical Examinations'!$A$1:$L$2336,9,FALSE) -> No | J8: =VLOOKUP(Medical_Examinations[[#This Row],[Customer ID]],'Medical Examinations'!A7:L2342,11,FALSE) -> Obesity | K8: =VLOOKUP(Medical_Examinations[[#This Row],[Customer ID]],'Medical Examinations'!A7:L2342,12,FALSE) -> Normal | L8: =VLOOKUP(Hospitalisation_Details[[#This Row],[Customer ID]],'Hospitalisation Details'!A7:K2348,10,FALSE) -> 26 Jun 2000 | M8: =VLOOKUP(Hospitalisation_Details[[#This Row],[Customer ID]],'Hospitalisation Details'!$A$1:$K$2342,6,FALSE) -> 1286 | N8: =VLOOKUP(Hospitalisation_Details[[#This Row],[Customer ID]],'Hospitalisation Details'!A7:K2348,7,FALSE) -> tier - 2 | O8: =VLOOKUP(Hospitalisation_Details[[#This Row],[Customer ID]],'Hospitalisation Details'!A7:K2348,8,FALSE) -> tier - 2 | P8: =VLOOKUP(Hospitalisation_Details[[#This Row],[Customer ID]],'Hospitalisation Details'!A7:K2348,9,FALSE) -> R1013 | Q8: =VLOOKUP(Hospitalisation_Details[[#This Row],[Customer ID]],'Hospitalisation Details'!$A$1:$K$2342,11,FALSE) -> 22
A9: Id8 | B9: =VLOOKUP(Customer_Names[[#This Row],[Customer ID]],Customer_Names[#All],2,FALSE) -> Hallman | C9: =VLOOKUP(Medical_Examinations[[#This Row],[Customer ID]],'Medical Examinations'!$A$1:$L$2336,2,FALSE) -> 54 | D9: =VLOOKUP(Medical_Examinations[[#This Row],[Customer ID]],'Medical Examinations'!$A$1:$L$2336,3,FALSE) -> 5 | E9: =VLOOKUP(Medical_Examinations[[#This Row],[Customer ID]],'Medical Examinations'!$A$1:$L$2336,4,FALSE) -> No | F9: =VLOOKUP(Medical_Examinations[[#This Row],[Customer ID]],'Medical Examinations'!$A$1:$L$2336,6,FALSE) -> No | G9: =VLOOKUP(Medical_Examinations[[#This Row],[Customer ID]],'Medical Examinations'!$A$1:$L$2336,7,FALSE) -> Yes | H9: =VLOOKUP(Medical_Examinations[[#This Row],[Customer ID]],'Medical Examinations'!$A$1:$L$2336,8,FALSE) -> 1 | I9: =VLOOKUP(Medical_Examinations[[#This Row],[Customer ID]],'Medical Examinations'!$A$1:$L$2336,9,FALSE) -> No | J9: =VLOOKUP(Medical_Examinations[[#This Row],[Customer ID]],'Medical Examinations'!A8:L2343,11,FALSE) -> Obesity | K9: =VLOOKUP(Medical_Examinations[[#This Row],[Customer ID]],'Medical Examinations'!A8:L2343,12,FALSE) -> Normal | L9: =VLOOKUP(Hospitalisation_Details[[#This Row],[Customer ID]],'Hospitalisation Details'!A8:K2349,10,FALSE) -> 4 Jun 1998 | M9: =VLOOKUP(Hospitalisation_Details[[#This Row],[Customer ID]],'Hospitalisation Details'!$A$1:$K$2342,6,FALSE) -> 1291 | N9: =VLOOKUP(Hospitalisation_Details[[#This Row],[Customer ID]],'Hospitalisation Details'!A8:K2349,7,FALSE) -> tier - 2 | O9: =VLOOKUP(Hospitalisation_Details[[#This Row],[Customer ID]],'Hospitalisation Details'!A8:K2349,8,FALSE) -> tier - 2 | P9: =VLOOKUP(Hospitalisation_Details[[#This Row],[Customer ID]],'Hospitalisation Details'!A8:K2349,9,FALSE) -> R1013 | Q9: =VLOOKUP(Hospitalisation_Details[[#This Row],[Customer ID]],'Hospitalisation Details'!$A$1:$K$2342,11,FALSE) -> 25
A10: Id9 | B10: =VLOOKUP(Customer_Names[[#This Row],[Customer ID]],Customer_Names[#All],2,FALSE) -> Moran | C10: =VLOOKUP(Medical_Examinations[[#This Row],[Customer ID]],'Medical Examinations'!$A$1:$L$2336,2,FALSE) -> 55 | D10: =VLOOKUP(Medical_Examinations[[#This Row],[Customer ID]],'Medical Examinations'!$A$1:$L$2336,3,FALSE) -> 5 | E10: =VLOOKUP(Medical_Examinations[[#This Row],[Customer ID]],'Medical Examinations'!$A$1:$L$2336,4,FALSE) -> No | F10: =VLOOKUP(Medical_Examinations[[#This Row],[Customer ID]],'Medical Examinations'!$A$1:$L$2336,6,FALSE) -> No | G10: =VLOOKUP(Medical_Examinations[[#This Row],[Customer ID]],'Medical Examinations'!$A$1:$L$2336,7,FALSE) -> No | H10: =VLOOKUP(Medical_Examinations[[#This Row],[Customer ID]],'Medical Examinations'!$A$1:$L$2336,8,FALSE) -> 1 | I10: =VLOOKUP(Medical_Examinations[[#This Row],[Customer ID]],'Medical Examinations'!$A$1:$L$2336,9,FALSE) -> No | J10: =VLOOKUP(Medical_Examinations[[#This Row],[Customer ID]],'Medical Examinations'!A9:L2344,11,FALSE) -> Obesity | K10: =VLOOKUP(Medical_Examinations[[#This Row],[Customer ID]],'Medical Examinations'!A9:L2344,12,FALSE) -> Normal | L10: =VLOOKUP(Hospitalisation_Details[[#This Row],[Customer ID]],'Hospitalisation Details'!A9:K2350,10,FALSE) -> 2 Dec 1999 | M10: =VLOOKUP(Hospitalisation_Details[[#This Row],[Customer ID]],'Hospitalisation Details'!$A$1:$K$2342,6,FALSE) -> 1304 | N10: =VLOOKUP(Hospitalisation_Details[[#This Row],[Customer ID]],'Hospitalisation Details'!A9:K2350,7,FALSE) -> tier - 2 | O10: =VLOOKUP(Hospitalisation_Details[[#This Row],[Customer ID]],'Hospitalisation Details'!A9:K2350,8,FALSE) -> tier - 2 | P10: =VLOOKUP(Hospitalisation_Details[[#This Row],[Customer ID]],'Hospitalisation Details'!A9:K2350,9,FALSE) -> R1013 | Q10: =VLOOKUP(Hospitalisation_Details[[#This Row],[Customer ID]],'Hospitalisation Details'!$A$1:$K$2342,11,FALSE) -> 23
A11: Id10 | B11: =VLOOKUP(Customer_Names[[#This Row],[Customer ID]],Customer_Names[#All],2,FALSE) -> Benner | C11: =VLOOKUP(Medical_Examinations[[#This Row],[Customer ID]],'Medical Examinations'!$A$1:$L$2336,2,FALSE) -> 47 | D11: =VLOOKUP(Medical_Examinations[[#This Row],[Customer ID]],'Medical Examinations'!$A$1:$L$2336,3,FALSE) -> 5 | E11: =VLOOKUP(Medical_Examinations[[#This Row],[Customer ID]],'Medical Examinations'!$A$1:$L$2336,4,FALSE) -> No | F11: =VLOOKUP(Medical_Examinations[[#This Row],[Customer ID]],'Medical Examinations'!$A$1:$L$2336,6,FALSE) -> No | G11: =VLOOKUP(Medical_Examinations[[#This Row],[Customer ID]],'Medical Examinations'!$A$1:$L$2336,7,FALSE) -> Yes | H11: =VLOOKUP(Medical_Examinations[[#This Row],[Customer ID]],'Medical Examinations'!$A$1:$L$2336,8,FALSE) -> 1 | I11: =VLOOKUP(Medical_Examinations[[#This Row],[Customer ID]],'Medical Examinations'!$A$1:$L$2336,9,FALSE) -> No | J11: =VLOOKUP(Medical_Examinations[[#This Row],[Customer ID]],'Medical Examinations'!A10:L2345,11,FALSE) -> Obesity | K11: =VLOOKUP(Medical_Examinations[[#This Row],[Customer ID]],'Medical Examinations'!A10:L2345,12,FALSE) -> Normal | L11: =VLOOKUP(Hospitalisation_Details[[#This Row],[Customer ID]],'Hospitalisation Details'!A10:K2351,10,FALSE) -> 13 Oct 2002 | M11: =VLOOKUP(Hospitalisation_Details[[#This Row],[Customer ID]],'Hospitalisation Details'!$A$1:$K$2342,6,FALSE) -> 1315 | N11: =VLOOKUP(Hospitalisation_Details[[#This Row],[Customer ID]],'Hospitalisation Details'!A10:K2351,7,FALSE) -> tier - 2 | O11: =VLOOKUP(Hospitalisation_Details[[#This Row],[Customer ID]],'Hospitalisation Details'!A10:K2351,8,FALSE) -> tier - 2 | P11: =VLOOKUP(Hospitalisation_Details[[#This Row],[Customer ID]],'Hospitalisation Details'!A10:K2351,9,FALSE) -> R1013 | Q11: =VLOOKUP(Hospitalisation_Details[[#This Row],[Customer ID]],'Hospitalisation Details'!$A$1:$K$2342,11,FALSE) -> 20
A12: Id11 | B12: =VLOOKUP(Customer_Names[[#This Row],[Customer ID]],Customer_Names[#All],2,FALSE) -> Fierro Vargas | C12: =VLOOKUP(Medical_Examinations[[#This Row],[Customer ID]],'Medical Examinations'!$A$1:$L$2336,2,FALSE) -> 54 | D12: =VLOOKUP(Medical_Examinations[[#This Row],[Customer ID]],'Medical Examinations'!$A$1:$L$2336,3,FALSE) -> 5 | E12: =VLOOKUP(Medical_Examinations[[#This Row],[Customer ID]],'Medical Examinations'!$A$1:$L$2336,4,FALSE) -> No | F12: =VLOOKUP(Medical_Examinations[[#This Row],[Customer ID]],'Medical Examinations'!$A$1:$L$2336,6,FALSE) -> No | G12: =VLOOKUP(Medical_Examinations[[#This Row],[Customer ID]],'Medical Examinations'!$A$1:$L$2336,7,FALSE) -> No | H12: =VLOOKUP(Medical_Examinations[[#This Row],[Customer ID]],'Medical Examinations'!$A$1:$L$2336,8,FALSE) -> 1 | I12: =VLOOKUP(Medical_Examinations[[#This Row],[Customer ID]],'Medical Examinations'!$A$1:$L$2336,9,FALSE) -> No | J12: =VLOOKUP(Medical_Examinations[[#This Row],[Customer ID]],'Medical Examinations'!A11:L2346,11,FALSE) -> Obesity | K12: =VLOOKUP(Medical_Examinations[[#This Row],[Customer ID]],'Medical Examinations'!A11:L2346,12,FALSE) -> Normal | L12: =VLOOKUP(Hospitalisation_Details[[#This Row],[Customer ID]],'Hospitalisation Details'!A11:K2352,10,FALSE) -> 6 Jul 1999 | M12: =VLOOKUP(Hospitalisation_Details[[#This Row],[Customer ID]],'Hospitalisation Details'!$A$1:$K$2342,6,FALSE) -> 1389 | N12: =VLOOKUP(Hospitalisation_Details[[#This Row],[Customer ID]],'Hospitalisation Details'!A11:K2352,7,FALSE) -> tier - 2 | O12: =VLOOKUP(Hospitalisation_Details[[#This Row],[Customer ID]],'Hospitalisation Details'!A11:K2352,8,FALSE) -> tier - 2 | P12: =VLOOKUP(Hospitalisation_Details[[#This Row],[Customer ID]],'Hospitalisation Details'!A11:K2352,9,FALSE) -> R1013 | Q12: =VLOOKUP(Hospitalisation_Details[[#This Row],[Customer ID]],'Hospitalisation Details'!$A$1:$K$2342,11,FALSE) -> 23
A13: Id12 | B13: =VLOOKUP(Customer_Names[[#This Row],[Customer ID]],Customer_Names[#All],2,FALSE) -> Franz | C13: =VLOOKUP(Medical_Examinations[[#This Row],[Customer ID]],'Medical Examinations'!$A$1:$L$2336,2,FALSE) -> 42 | D13: =VLOOKUP(Medical_Examinations[[#This Row],[Customer ID]],'Medical Examinations'!$A$1:$L$2336,3,FALSE) -> 5 | E13: =VLOOKUP(Medical_Examinations[[#This Row],[Customer ID]],'Medical Examinations'!$A$1:$L$2336,4,FALSE) -> No | F13: =VLOOKUP(Medical_Examinations[[#This Row],[Customer ID]],'Medical Examinations'!$A$1:$L$2336,6,FALSE) -> No | G13: =VLOOKUP(Medical_Examinations[[#This Row],[Customer ID]],'Medical Examinations'!$A$1:$L$2336,7,FALSE) -> No | H13: =VLOOKUP(Medical_Examinations[[#This Row],[Customer ID]],'Medical Examinations'!$A$1:$L$2336,8,FALSE) -> 1 | I13: =VLOOKUP(Medical_Examinations[[#This Row],[Customer ID]],'Medical Examinations'!$A$1:$L$2336,9,FALSE) -> No | J13: =VLOOKUP(Medical_Examinations[[#This Row],[Customer ID]],'Medical Examinations'!A12:L2347,11,FALSE) -> Obesity | K13: =VLOOKUP(Medical_Examinations[[#This Row],[Customer ID]],'Medical Examinations'!A12:L2347,12,FALSE) -> Normal | L13: =VLOOKUP(Hospitalisation_Details[[#This Row],[Customer ID]],'Hospitalisation Details'!A12:K2353,10,FALSE) -> 14 Nov 2002 | M13: =VLOOKUP(Hospitalisation_Details[[#This Row],[Customer ID]],'Hospitalisation Details'!$A$1:$K$2342,6,FALSE) -> 1390 | N13: =VLOOKUP(Hospitalisation_Details[[#This Row],[Customer ID]],'Hospitalisation Details'!A12:K2353,7,FALSE) -> tier - 2 | O13: =VLOOKUP(Hospitalisation_Details[[#This Row],[Customer ID]],'Hospitalisation Details'!A12:K2353,8,FALSE) -> tier - 2 | P13: =VLOOKUP(Hospitalisation_Details[[#This Row],[Customer ID]],'Hospitalisation Details'!A12:K2353,9,FALSE) -> R1013 | Q13: =VLOOKUP(Hospitalisation_Details[[#This Row],[Customer ID]],'Hospitalisation Details'!$A$1:$K$2342,11,FALSE) -> 20
A14: Id13 | B14: =VLOOKUP(Customer_Names[[#This Row],[Customer ID]],Customer_Names[#All],2,FALSE) -> Foster | C14: =VLOOKUP(Medical_Examinations[[#This Row],[Customer ID]],'Medical Examinations'!$A$1:$L$2336,2,FALSE) -> 41 | D14: =VLOOKUP(Medical_Examinations[[#This Row],[Customer ID]],'Medical Examinations'!$A$1:$L$2336,3,FALSE) -> 5 | E14: =VLOOKUP(Medical_Examinations[[#This Row],[Customer ID]],'Medical Examinations'!$A$1:$L$2336,4,FALSE) -> No | F14: =VLOOKUP(Medical_Examinations[[#This Row],[Customer ID]],'Medical Examinations'!$A$1:$L$2336,6,FALSE) -> No | G14: =VLOOKUP(Medical_Examinations[[#This Row],[Customer ID]],'Medical Examinations'!$A$1:$L$2336,7,FALSE) -> No | H14: =VLOOKUP(Medical_Examinations[[#This Row],[Customer ID]],'Medical Examinations'!$A$1:$L$2336,8,FALSE) -> 1 | I14: =VLOOKUP(Medical_Examinations[[#This Row],[Customer ID]],'Medical Examinations'!$A$1:$L$2336,9,FALSE) -> No | J14: =VLOOKUP(Medical_Examinations[[#This Row],[Customer ID]],'Medical Examinations'!A13:L2348,11,FALSE) -> Obesity | K14: =VLOOKUP(Medical_Examinations[[#This Row],[Customer ID]],'Medical Examinations'!A13:L2348,12,FALSE) -> Normal | L14: =VLOOKUP(Hospitalisation_Details[[#This Row],[Customer ID]],'Hospitalisation Details'!A13:K2354,10,FALSE) -> 5 Sep 1998 | M14: =VLOOKUP(Hospitalisation_Details[[#This Row],[Customer ID]],'Hospitalisation Details'!$A$1:$K$2342,6,FALSE) -> 1400 | N14: =VLOOKUP(Hospitalisation_Details[[#This Row],[Customer ID]],'Hospitalisation Details'!A13:K2354,7,FALSE) -> tier - 2 | O14: =VLOOKUP(Hospitalisation_Details[[#This Row],[Customer ID]],'Hospitalisation Details'!A13:K2354,8,FALSE) -> tier - 2 | P14: =VLOOKUP(Hospitalisation_Details[[#This Row],[Customer ID]],'Hospitalisation Details'!A13:K2354,9,FALSE) -> R1013 | Q14: =VLOOKUP(Hospitalisation_Details[[#This Row],[Customer ID]],'Hospitalisation Details'!$A$1:$K$2342,11,FALSE) -> 24
A15: Id14 | B15: =VLOOKUP(Customer_Names[[#This Row],[Customer ID]],Customer_Names[#All],2,FALSE) -> Tenorio | C15: =VLOOKUP(Medical_Examinations[[#This Row],[Customer ID]],'Medical Examinations'!$A$1:$L$2336,2,FALSE) -> 53 | D15: =VLOOKUP(Medical_Examinations[[#This Row],[Customer ID]],'Medical Examinations'!$A$1:$L$2336,3,FALSE) -> 5 | E15: =VLOOKUP(Medical_Examinations[[#This Row],[Customer ID]],'Medical Examinations'!$A$1:$L$2336,4,FALSE) -> No | F15: =VLOOKUP(Medical_Examinations[[#This Row],[Customer ID]],'Medical Examinations'!$A$1:$L$2336,6,FALSE) -> No | G15: =VLOOKUP(Medical_Examinations[[#This Row],[Customer ID]],'Medical Examinations'!$A$1:$L$2336,7,FALSE) -> Yes | H15: =VLOOKUP(Medical_Examinations[[#This Row],[Customer ID]],'Medical Examinations'!$A$1:$L$2336,8,FALSE) -> 1 | I15: =VLOOKUP(Medical_Examinations[[#This Row],[Customer ID]],'Medical Examinations'!$A$1:$L$2336,9,FALSE) -> No | J15: =VLOOKUP(Medical_Examinations[[#This Row],[Customer ID]],'Medical Examinations'!A14:L2349,11,FALSE) -> Obesity | K15: =VLOOKUP(Medical_Examinations[[#This Row],[Customer ID]],'Medical Examinations'!A14:L2349,12,FALSE) -> Normal | L15: =VLOOKUP(Hospitalisation_Details[[#This Row],[Customer ID]],'Hospitalisation Details'!A14:K2355,10,FALSE) -> 23 Aug 2001 | M15: =VLOOKUP(Hospitalisation_Details[[#This Row],[Customer ID]],'Hospitalisation Details'!$A$1:$K$2342,6,FALSE) -> 1421 | N15: =VLOOKUP(Hospitalisation_Details[[#This Row],[Customer ID]],'Hospitalisation Details'!A14:K2355,7,FALSE) -> tier - 2 | O15: =VLOOKUP(Hospitalisation_Details[[#This Row],[Customer ID]],'Hospitalisation Details'!A14:K2355,8,FALSE) -> tier - 2 | P15: =VLOOKUP(Hospitalisation_Details[[#This Row],[Customer ID]],'Hospitalisation Details'!A14:K2355,9,FALSE) -> R1013 | Q15: =VLOOKUP(Hospitalisation_Details[[#This Row],[Customer ID]],'Hospitalisation Details'!$A$1:$K$2342,11,FALSE) -> 21
A16: Id15 | B16: =VLOOKUP(Customer_Names[[#This Row],[Customer ID]],Customer_Names[#All],2,FALSE) -> Rios | C16: =VLOOKUP(Medical_Examinations[[#This Row],[Customer ID]],'Medical Examinations'!$A$1:$L$2336,2,FALSE) -> 27 | D16: =VLOOKUP(Medical_Examinations[[#This Row],[Customer ID]],'Medical Examinations'!$A$1:$L$2336,3,FALSE) -> 5 | E16: =VLOOKUP(Medical_Examinations[[#This Row],[Customer ID]],'Medical Examinations'!$A$1:$L$2336,4,FALSE) -> No | F16: =VLOOKUP(Medical_Examinations[[#This Row],[Customer ID]],'Medical Examinations'!$A$1:$L$2336,6,FALSE) -> No | G16: =VLOOKUP(Medical_Examinations[[#This Row],[Customer ID]],'Medical Examinations'!$A$1:$L$2336,7,FALSE) -> No | H16: =VLOOKUP(Medical_Examinations[[#This Row],[Customer ID]],'Medical Examinations'!$A$1:$L$2336,8,FALSE) -> 1 | I16: =VLOOKUP(Medical_Examinations[[#This Row],[Customer ID]],'Medical Examinations'!$A$1:$L$2336,9,FALSE) -> No | J16: =VLOOKUP(Medical_Examinations[[#This Row],[Customer ID]],'Medical Examinations'!A15:L2350,11,FALSE) -> Overweight | K16: =VLOOKUP(Medical_Examinations[[#This Row],[Customer ID]],'Medical Examinations'!A15:L2350,12,FALSE) -> Normal | L16: =VLOOKUP(Hospitalisation_Details[[#This Row],[Customer ID]],'Hospitalisation Details'!A15:K2356,10,FALSE) -> 5 Dec 1997 | M16: =VLOOKUP(Hospitalisation_Details[[#This Row],[Customer ID]],'Hospitalisation Details'!$A$1:$K$2342,6,FALSE) -> 1422 | N16: =VLOOKUP(Hospitalisation_Details[[#This Row],[Customer ID]],'Hospitalisation Details'!A15:K2356,7,FALSE) -> tier - 2 | O16: =VLOOKUP(Hospitalisation_Details[[#This Row],[Customer ID]],'Hospitalisation Details'!A15:K2356,8,FALSE) -> tier - 2 | P16: =VLOOKUP(Hospitalisation_Details[[#This Row],[Customer ID]],'Hospitalisation Details'!A15:K2356,9,FALSE) -> R1013 | Q16: =VLOOKUP(Hospitalisation_Details[[#This Row],[Customer ID]],'Hospitalisation Details'!$A$1:$K$2342,11,FALSE) -> 25
A17: Id16 | B17: =VLOOKUP(Customer_Names[[#This Row],[Customer ID]],Customer_Names[#All],2,FALSE) -> Viau-Dupuis | C17: =VLOOKUP(Medical_Examinations[[#This Row],[Customer ID]],'Medical Examinations'!$A$1:$L$2336,2,FALSE) -> 37 | D17: =VLOOKUP(Medical_Examinations[[#This Row],[Customer ID]],'Medical Examinations'!$A$1:$L$2336,3,FALSE) -> 5 | E17: =VLOOKUP(Medical_Examinations[[#This Row],[Customer ID]],'Medical Examinations'!$A$1:$L$2336,4,FALSE) -> No | F17: =VLOOKUP(Medical_Examinations[[#This Row],[Customer ID]],'Medical Examinations'!$A$1:$L$2336,6,FALSE) -> No | G17: =VLOOKUP(Medical_Examinations[[#This Row],[Customer ID]],'Medical Examinations'!$A$1:$L$2336,7,FALSE) -> Yes | H17: =VLOOKUP(Medical_Examinations[[#This Row],[Customer ID]],'Medical Examinations'!$A$1:$L$2336,8,FALSE) -> 1 | I17: =VLOOKUP(Medical_Examinations[[#This Row],[Customer ID]],'Medical Examinations'!$A$1:$L$2336,9,FALSE) -> No | J17: =VLOOKUP(Medical_Examinations[[#This Row],[Customer ID]],'Medical Examinations'!A16:L2351,11,FALSE) -> Obesity | K17: =VLOOKUP(Medical_Examinations[[#This Row],[Customer ID]],'Medical Examinations'!A16:L2351,12,FALSE) -> Normal | L17: =VLOOKUP(Hospitalisation_Details[[#This Row],[Customer ID]],'Hospitalisation Details'!A16:K2357,10,FALSE) -> 1 Sep 2000 | M17: =VLOOKUP(Hospitalisation_Details[[#This Row],[Customer ID]],'Hospitalisation Details'!$A$1:$K$2342,6,FALSE) -> 1438 | N17: =VLOOKUP(Hospitalisation_Details[[#This Row],[Customer ID]],'Hospitalisation Details'!A16:K2357,7,FALSE) -> tier - 2 | O17: =VLOOKUP(Hospitalisation_Details[[#This Row],[Customer ID]],'Hospitalisation Details'!A16:K2357,8,FALSE) -> tier - 2 | P17: =VLOOKUP(Hospitalisation_Details[[#This Row],[Customer ID]],'Hospitalisation Details'!A16:K2357,9,FALSE) -> R1013 | Q17: =VLOOKUP(Hospitalisation_Details[[#This Row],[Customer ID]],'Hospitalisation Details'!$A$1:$K$2342,11,FALSE) -> 22
A18: Id17 | B18: =VLOOKUP(Customer_Names[[#This Row],[Customer ID]],Customer_Names[#All],2,FALSE) -> Cronin | C18: =VLOOKUP(Medical_Examinations[[#This Row],[Customer ID]],'Medical Examinations'!$A$1:$L$2336,2,FALSE) -> 50 | D18: =VLOOKUP(Medical_Examinations[[#This Row],[Customer ID]],'Medical Examinations'!$A$1:$L$2336,3,FALSE) -> 5 | E18: =VLOOKUP(Medical_Examinations[[#This Row],[Customer ID]],'Medical Examinations'!$A$1:$L$2336,4,FALSE) -> No | F18: =VLOOKUP(Medical_Examinations[[#This Row],[Customer ID]],'Medical Examinations'!$A$1:$L$2336,6,FALSE) -> No | G18: =VLOOKUP(Medical_Examinations[[#This Row],[Customer ID]],'Medical Examinations'!$A$1:$L$2336,7,FALSE) -> Yes | H18: =VLOOKUP(Medical_Examinations[[#This Row],[Customer ID]],'Medical Examinations'!$A$1:$L$2336,8,FALSE) -> 1 | I18: =VLOOKUP(Medical_Examinations[[#This Row],[Customer ID]],'Medical Examinations'!$A$1:$L$2336,9,FALSE) -> No | J18: =VLOOKUP(Medical_Examinations[[#This Row],[Customer ID]],'Medical Examinations'!A17:L2352,11,FALSE) -> Obesity | K18: =VLOOKUP(Medical_Examinations[[#This Row],[Customer ID]],'Medical Examinations'!A17:L2352,12,FALSE) -> Normal | L18: =VLOOKUP(Hospitalisation_Details[[#This Row],[Customer ID]],'Hospitalisation Details'!A17:K2358,10,FALSE) -> 20 Jun 2003 | M18: =VLOOKUP(Hospitalisation_Details[[#This Row],[Customer ID]],'Hospitalisation Details'!$A$1:$K$2342,6,FALSE) -> 1467 | N18: =VLOOKUP(Hospitalisation_Details[[#This Row],[Customer ID]],'Hospitalisation Details'!A17:K2358,7,FALSE) -> tier - 2 | O18: =VLOOKUP(Hospitalisation_Details[[#This Row],[Customer ID]],'Hospitalisation Details'!A17:K2358,8,FALSE) -> tier - 2 | P18: =VLOOKUP(Hospitalisation_Details[[#This Row],[Customer ID]],'Hospitalisation Details'!A17:K2358,9,FALSE) -> R1013 | Q18: =VLOOKUP(Hospitalisation_Details[[#This Row],[Customer ID]],'Hospitalisation Details'!$A$1:$K$2342,11,FALSE) -> 19
A19: Id18 | B19: =VLOOKUP(Customer_Names[[#This Row],[Customer ID]],Customer_Names[#All],2,FALSE) -> Noordstar | C19: =VLOOKUP(Medical_Examinations[[#This Row],[Customer ID]],'Medical Examinations'!$A$1:$L$2336,2,FALSE) -> 43 | D19: =VLOOKUP(Medical_Examinations[[#This Row],[Customer ID]],'Medical Examinations'!$A$1:$L$2336,3,FALSE) -> 5 | E19: =VLOOKUP(Medical_Examinations[[#This Row],[Customer ID]],'Medical Examinations'!$A$1:$L$2336,4,FALSE) -> No | F19: =VLOOKUP(Medical_Examinations[[#This Row],[Customer ID]],'Medical Examinations'!$A$1:$L$2336,6,FALSE) -> No | G19: =VLOOKUP(Medical_Examinations[[#This Row],[Customer ID]],'Medical Examinations'!$A$1:$L$2336,7,FALSE) -> No | H19: =VLOOKUP(Medical_Examinations[[#This Row],[Customer ID]],'Medical Examinations'!$A$1:$L$2336,8,FALSE) -> 1 | I19: =VLOOKUP(Medical_Examinations[[#This Row],[Customer ID]],'Medical Examinations'!$A$1:$L$2336,9,FALSE) -> No | J19: =VLOOKUP(Medical_Examinations[[#This Row],[Customer ID]],'Medical Examinations'!A18:L2353,11,FALSE) -> Obesity | K19: =VLOOKUP(Medical_Examinations[[#This Row],[Customer ID]],'Medical Examinations'!A18:L2353,12,FALSE) -> Normal | L19: =VLOOKUP(Hospitalisation_Details[[#This Row],[Customer ID]],'Hospitalisation Details'!A18:K2359,10,FALSE) -> 19 Jun 1998 | M19: =VLOOKUP(Hospitalisation_Details[[#This Row],[Customer ID]],'Hospitalisation Details'!$A$1:$K$2342,6,FALSE) -> 1497 | N19: =VLOOKUP(Hospitalisation_Details[[#This Row],[Customer ID]],'Hospitalisation Details'!A18:K2359,7,FALSE) -> tier - 2 | O19: =VLOOKUP(Hospitalisation_Details[[#This Row],[Customer ID]],'Hospitalisation Details'!A18:K2359,8,FALSE) -> tier - 2 | P19: =VLOOKUP(Hospitalisation_Details[[#This Row],[Customer ID]],'Hospitalisation Details'!A18:K2359,9,FALSE) -> R1013 | Q19: =VLOOKUP(Hospitalisation_Details[[#This Row],[Customer ID]],'Hospitalisation Details'!$A$1:$K$2342,11,FALSE) -> 24
... A2336: Id2335 | B2336: =VLOOKUP(Customer_Names[[#This Row],[Customer ID]],Customer_Names[#All],2,FALSE) -> German | C2336: =VLOOKUP(Medical_Examinations[[#This Row],[Customer ID]],'Medical Examinations'!$A$1:$L$2336,2,FALSE) -> 25 | D2336: =VLOOKUP(Medical_Examinations[[#This Row],[Customer ID]],'Medical Examinations'!$A$1:$L$2336,3,FALSE) -> 5 | E2336: =VLOOKUP(Medical_Examinations[[#This Row],[Customer ID]],'Medical Examinations'!$A$1:$L$2336,4,FALSE) -> No | F2336: =VLOOKUP(Medical_Examinations[[#This Row],[Customer ID]],'Medical Examinations'!$A$1:$L$2336,6,FALSE) -> yes | G2336: =VLOOKUP(Medical_Examinations[[#This Row],[Customer ID]],'Medical Examinations'!$A$1:$L$2336,7,FALSE) -> No | H2336: =VLOOKUP(Medical_Examinations[[#This Row],[Customer ID]],'Medical Examinations'!$A$1:$L$2336,8,FALSE) -> 1 | I2336: =VLOOKUP(Medical_Examinations[[#This Row],[Customer ID]],'Medical Examinations'!$A$1:$L$2336,9,FALSE) -> Unknown | J2336: =VLOOKUP(Medical_Examinations[[#This Row],[Customer ID]],'Medical Examinations'!A2335:L4670,11,FALSE) -> Overweight | K2336: =VLOOKUP(Medical_Examinations[[#This Row],[Customer ID]],'Medical Examinations'!A2335:L4670,12,FALSE) -> Normal | L2336: =VLOOKUP(Hospitalisation_Details[[#This Row],[Customer ID]],'Hospitalisation Details'!A2335:K4676,10,FALSE) -> 21 Jun 1958 | M2336: =VLOOKUP(Hospitalisation_Details[[#This Row],[Customer ID]],'Hospitalisation Details'!$A$1:$K$2342,6,FALSE) -> 16085 | N2336: =VLOOKUP(Hospitalisation_Details[[#This Row],[Customer ID]],'Hospitalisation Details'!A2335:K4676,7,FALSE) -> tier - 2 | O2336: =VLOOKUP(Hospitalisation_Details[[#This Row],[Customer ID]],'Hospitalisation Details'!A2335:K4676,8,FALSE) -> tier - 2 | P2336: =VLOOKUP(Hospitalisation_Details[[#This Row],[Customer ID]],'Hospitalisation Details'!A2335:K4676,9,FALSE) -> R1013 | Q2336: =VLOOKUP(Hospitalisation_Details[[#This Row],[Customer ID]],'Hospitalisation Details'!$A$1:$K$2342,11,FALSE) -> 64
